Workbook
Name netropenia: 'FEDER Dataset'!$3:$3

Sheet FEDER Dataset
A1: report_id | B1: receive_date | C1: year | D1: month | E1: quarter | F1: serious | G1: serious_flags | H1: is_fatal | I1: is_hospitalized | J1: is_life_threat | K1: is_disabling | L1: reactions | M1: primary_reaction | N1: reaction_outcomes | O1: patient_recovered | P1: num_reactions | Q1: suspect_drug | R1: brand_name | S1: drug_route | T1: drug_indication | U1: manufacturer | V1: pharm_class | W1: num_drugs | X1: drug_count_category | Y1: patient_age_years | Z1: age_group | AA1: patient_sex | AB1: patient_weight_kg | AC1: country | AD1: report_age_days
A2: 10136674 | B2: 45659 | C2: 2025 | D2: 1 | E2: 2025Q1 | F2: Yes | G2: Hospitalization | H2: FALSE | I2: TRUE | J2: FALSE | K2: FALSE | L2: Pneumonia; Staphylococcal infection; Sepsis | M2: Pneumonia | N2: Recovered | O2: TRUE | P2: 3 | Q2: USTEKINUMAB | R2: STELARA | S2: 58 | T2: Psoriasis | U2: Janssen Biotech, Inc. | V2: Interleukin-12 Antagonist [EPC]; Interleukin-23 Antagonist [EPC] | W2: 12 | X2: Polypharmacy(6+) | Y2: 23 | Z2: Adult(19-40) | AA2: Female | AB2: 55 | AC2: RS | AD2: 450
A3: 10233235 | B3: 45664 | C3: 2025 | D3: 1 | E3: 2025Q1 | F3: Yes | G3: Death; Life-Threatening | H3: TRUE | I3: FALSE | J3: TRUE | K3: FALSE | L3: Cerebrovascular accident | M3: Cerebrovascular accident | N3: Unknown | O3: FALSE | P3: 1 | Q3: TEMODAL | R3: Unknown | S3: 48 | T3: Glioblastoma | U3: Unknown | V3: Unknown | W3: 2 | X3: 2-3 Drugs | Z3: Unknown | AA3: Unknown | AC3: CA | AD3: 445
A4: 10285496 | B4: 45685 | C4: 2025 | D4: 1 | E4: 2025Q1 | F4: Yes | G4: None | H4: FALSE | I4: FALSE | J4: FALSE | K4: FALSE | L4: Alopecia; Weight decreased; Gastrointestinal disorder; Vitamin D deficiency; Upper limb fracture | M4: Alopecia | N4: Unknown; Recovered | O4: TRUE | P4: 11 | Q4: VISMODEGIB | R4: ERIVEDGE | S4: 50 | T4: Basal Cell Carcinoma | U4: Genentech, Inc. | V4: Hedgehog Pathway Inhibitor [EPC] | W4: 7 | X4: Polypharmacy(6+) | Y4: 58 | Z4: Middle-Aged(41-65) | AA4: Male | AC4: US | AD4: 424
A5: 10356309 | B5: 45688 | C5: 2025 | D5: 1 | E5: 2025Q1 | F5: Yes | G5: Hospitalization | H5: FALSE | I5: TRUE | J5: FALSE | K5: FALSE | L5: Pneumonia; Obstructive airways disorder; Lower respiratory tract infection; Forced expiratory volume decreased; Irritability | M5: Pneumonia | N5: Unknown; Not Recovered; Recovered; Recovering | O5: FALSE | P5: 59 | Q5: OMALIZUMAB | R5: XOLAIR | S5: 58 | T5: Asthma | U5: Genentech, Inc. | V5: Anti-IgE [EPC] | W5: 40 | X5: Polypharmacy(6+) | Y5: 64 | Z5: Middle-Aged(41-65) | AA5: Female | AC5: CA | AD5: 421
A6: 10450109 | B6: 45670 | C6: 2025 | D6: 1 | E6: 2025Q1 | F6: Yes | G6: None | H6: FALSE | I6: FALSE | J6: FALSE | K6: FALSE | L6: Retinal phototoxicity; Visual impairment; Visual field defect; Visual acuity reduced | M6: Retinal phototoxicity | N6: Recovered | O6: TRUE | P6: 4 | Q6: SURMONTIL | R6: Unknown | S6: 48 | T6: Depression | U6: Unknown | V6: Unknown | W6: 4 | X6: 4-5 Drugs | Y6: 75 | Z6: Senior(66-80) | AA6: Male | AC6: FR | AD6: 439
A7: 10607501 | B7: 45673 | C7: 2025 | D7: 1 | E7: 2025Q1 | F7: Yes | G7: Death; Hospitalization | H7: TRUE | I7: TRUE | J7: FALSE | K7: FALSE | L7: Death; Haematoma | M7: Death | N7: Unknown; Not Recovered | O7: FALSE | P7: 2 | Q7: FONDAPARINUX | R7: Unknown | S7: 58 | T7: Pulmonary Embolism | U7: Unknown | V7: Unknown | W7: 3 | X7: 2-3 Drugs | Y7: 71 | Z7: Senior(66-80) | AA7: Male | AC7: FR | AD7: 436
A8: 10660602 | B8: 45673 | C8: 2025 | D8: 1 | E8: 2025Q1 | F8: Yes | G8: None | H8: FALSE | I8: FALSE | J8: FALSE | K8: FALSE | L8: Overdose; Drug dependence; Blood pressure increased; Hyperhidrosis; Drug withdrawal syndrome | M8: Overdose | N8: Unknown; Not Recovered | O8: FALSE | P8: 21 | Q8: OXYCODONE HYDROCHLORIDE | R8: OXYCONTIN | S8: 48 | T8: Pain | U8: Purdue Pharma Lp | V8: Unknown | W8: 40 | X8: Polypharmacy(6+) | Z8: Unknown | AA8: Male | AB8: 104.31 | AC8: US | AD8: 436
A9: 10675738 | B9: 45663 | C9: 2025 | D9: 1 | E9: 2025Q1 | F9: Yes | G9: None | H9: FALSE | I9: FALSE | J9: FALSE | K9: FALSE | L9: Pyoderma gangrenosum; Palmoplantar pustulosis; Sacroiliitis; Rheumatoid arthritis | M9: Pyoderma gangrenosum | N9: Recovered | O9: TRUE | P9: 4 | Q9: ADALIMUMAB; ADALIMUMAB-AATY; ADALIMUMAB-ADAZ; ADALIMUMAB-FKJP | R9: HUMIRA; ADALIMUMAB | S9: 58 | T9: Rheumatoid Arthritis | U9: Cordavis Limited; Celltrion Usa, Inc.; Abbvie Inc.; Sandoz Inc; Biocon Biologics Inc | V9: Tumor Necrosis Factor Blocker [EPC] | W9: 2 | X9: 2-3 Drugs | Y9: 82 | Z9: Elderly(81+) | AA9: Female | AB9: 55 | AC9: ES | AD9: 446
A10: 10786604 | B10: 45688 | C10: 2025 | D10: 1 | E10: 2025Q1 | F10: No | G10: None | H10: FALSE | I10: FALSE | J10: FALSE | K10: FALSE | L10: Drug resistance | M10: Drug resistance | N10: Unknown | O10: FALSE | P10: 1 | Q10: IMATINIB | R10: IMATINIB MESYLATE; IMATINIB | S10: 65 | T10: Chronic Myeloid Leukaemia | U10: Mylan Pharmaceuticals Inc.; Dr.Reddy'S Laboratories Inc | V10: Unknown | W10: 3 | X10: 2-3 Drugs | Z10: Unknown | AA10: Unknown | AC10: FI | AD10: 421
A11: 10853820 | B11: 45687 | C11: 2025 | D11: 1 | E11: 2025Q1 | F11: Yes | G11: Hospitalization | H11: FALSE | I11: TRUE | J11: FALSE | K11: FALSE | L11: Withdrawal syndrome; Drug abuse; Confusional state; Psychomotor hyperactivity; Tremor | M11: Withdrawal syndrome | N11: Unknown; Recovered | O11: TRUE | P11: 6 | Q11: ZOLPIDEM TARTRATE | R11: ZOLPIDEM | S11: 48 | T11: Insomnia | U11: Aci Healthcare Usa, Inc | V11: Unknown | W11: 6 | X11: Polypharmacy(6+) | Z11: Unknown | AA11: Female | AC11: CZ | AD11: 422
A12: 10876704 | B12: 45663 | C12: 2025 | D12: 1 | E12: 2025Q1 | F12: Yes | G12: None | H12: FALSE | I12: FALSE | J12: FALSE | K12: FALSE | L12: Serotonin syndrome; Obesity; Essential tremor | M12: Serotonin syndrome | N12: Recovered | O12: TRUE | P12: 3 | Q12: LACOSAMIDE | R12: VIMPAT | S12: 48 | T12: Seizure | U12: Ucb, Inc. | V12: Unknown | W12: 16 | X12: Polypharmacy(6+) | Y12: 67 | Z12: Senior(66-80) | AA12: Female | AC12: US | AD12: 446
A13: 10928940 | B13: 45660 | C13: 2025 | D13: 1 | E13: 2025Q1 | F13: Yes | G13: None | H13: FALSE | I13: FALSE | J13: FALSE | K13: FALSE | L13: Gynaecomastia; Emotional distress; Abnormal weight gain | M13: Gynaecomastia | N13: Unknown; Recovered | O13: TRUE | P13: 3 | Q13: RISPERIDONE | R13: RISPERIDONE; UZEDY; PERSERIS; RYKINDO EXTENDED-RELEASE MICROSPHERES; RISPERDAL | S13: 48 | T13: Bipolar Disorder | U13: Amneal Pharmaceuticals Llc; Lupin Pharmaceuticals, Inc.; Amneal Pharmaceuticals Ny Llc; Janssen Pharmaceutical, Inc.; Jubilant Cadista Pharmacuticals Inc. | V13: Atypical Antipsychotic [EPC] | W13: 10 | X13: Polypharmacy(6+) | Y13: 13 | Z13: Teen(13-18) | AA13: Male | AB13: 124.74 | AC13: US | AD13: 449
A14: 10943373 | B14: 45680 | C14: 2025 | D14: 1 | E14: 2025Q1 | F14: No | G14: None | H14: FALSE | I14: FALSE | J14: FALSE | K14: FALSE | L14: Emotional disorder; Gynaecomastia; Weight increased | M14: Emotional disorder | N14: Unknown | O14: FALSE | P14: 3 | Q14: RISPERIDONE | R14: RISPERDAL | S14: 48 | T14: Product Used For Unknown Indication | U14: Janssen Pharmaceuticals, Inc. | V14: Atypical Antipsychotic [EPC] | W14: 4 | X14: 4-5 Drugs | Z14: Unknown | AA14: Male | AC14: US | AD14: 429
A15: 10943649 | B15: 45680 | C15: 2025 | D15: 1 | E15: 2025Q1 | F15: No | G15: None | H15: FALSE | I15: FALSE | J15: FALSE | K15: FALSE | L15: Gynaecomastia; Emotional disorder; Weight increased | M15: Gynaecomastia | N15: Unknown | O15: FALSE | P15: 3 | Q15: RISPERIDONE | R15: RISPERDAL | S15: 48 | T15: Product Used For Unknown Indication | U15: Janssen Pharmaceuticals, Inc. | V15: Atypical Antipsychotic [EPC] | W15: 1 | X15: Single | Z15: Unknown | AA15: Male | AC15: US | AD15: 429
A16: 10946040 | B16: 45680 | C16: 2025 | D16: 1 | E16: 2025Q1 | F16: No | G16: None | H16: FALSE | I16: FALSE | J16: FALSE | K16: FALSE | L16: Gynaecomastia; Weight increased; Emotional distress; Off label use | M16: Gynaecomastia | N16: Unknown | O16: FALSE | P16: 4 | Q16: RISPERIDONE | R16: RISPERDAL | S16: 48 | T16: Attention Deficit Hyperactivity Disorder | U16: Janssen Pharmaceuticals, Inc. | V16: Atypical Antipsychotic [EPC] | W16: 3 | X16: 2-3 Drugs | Z16: Unknown | AA16: Male | AC16: US | AD16: 429
A17: 10975876 | B17: 45687 | C17: 2025 | D17: 1 | E17: 2025Q1 | F17: Yes | G17: Hospitalization | H17: FALSE | I17: TRUE | J17: FALSE | K17: FALSE | L17: Rectal haemorrhage; Haematochezia; Cystitis; Blood pressure decreased; Malignant neoplasm progression | M17: Rectal haemorrhage | N17: Unknown; Not Recovered; Recovered; Recovering | O17: FALSE | P17: 68 | Q17: OCTREOTIDE ACETATE | R17: SANDOSTATIN LAR DEPOT | S17: 30 | T17: Neuroendocrine Tumour | U17: Novartis Pharmaceuticals Corporation | V17: Unknown | W17: 12 | X17: Polypharmacy(6+) | Z17: Unknown | AA17: Female | AC17: CA | AD17: 422
A18: 11069598 | B18: 45672 | C18: 2025 | D18: 1 | E18: 2025Q1 | F18: Yes | G18: Death | H18: TRUE | I18: FALSE | J18: FALSE | K18: FALSE | L18: Abscess oral; Arthropathy; Back pain; Blood pressure increased; Dental caries | M18: Abscess oral | N18: Unknown; Not Recovered | O18: FALSE | P18: 37 | Q18: RIVAROXABAN | R18: XARELTO | S18: 48 | T18: Product Used For Unknown Indication | U18: Janssen Pharmaceuticals, Inc. | V18: Factor Xa Inhibitor [EPC] | W18: 23 | X18: Polypharmacy(6+) | Y18: 83 | Z18: Elderly(81+) | AA18: Female | AB18: 72 | AC18: CA | AD18: 437
A19: 11101084 | B19: 45688 | C19: 2025 | D19: 1 | E19: 2025Q1 | F19: Yes | G19: Death | H19: TRUE | I19: FALSE | J19: FALSE | K19: FALSE | L19: Peritonitis; Respiratory arrest; Intestinal gangrene; Septic shock; Extra dose administered | M19: Peritonitis | N19: Unknown | O19: FALSE | P19: 9 | Q19: MORPHINE SULFATE | R19: MORPHINE SULFATE; INFUMORPH 200; INFUMORPH 500; MORPHINE SULFATE EXTENDED RELEASE; MS CONTIN | S19: 42 | T19: Product Used For Unknown Indication | U19: International Medication Systems, Limited; Hikma Pharmaceuticals Usa Inc.; Rhodes Pharmaceuticals L. P.; Hospira, Inc.; Fresenius Kabi, Usa Llc | V19: Unknown | W19: 2 | X19: 2-3 Drugs | Y19: 57 | Z19: Middle-Aged(41-65) | AA19: Male | AC19: US | AD19: 421
A20: 11140907 | B20: 45680 | C20: 2025 | D20: 1 | E20: 2025Q1 | F20: No | G20: None | H20: FALSE | I20: FALSE | J20: FALSE | K20: FALSE | L20: Gynaecomastia; Weight increased; Emotional disorder | M20: Gynaecomastia | N20: Unknown | O20: FALSE | P20: 3 | Q20: RISPERIDONE | R20: RISPERDAL | S20: 48 | T20: Product Used For Unknown Indication | U20: Janssen Pharmaceuticals, Inc. | V20: Atypical Antipsychotic [EPC] | W20: 1 | X20: Single | Z20: Unknown | AA20: Male | AC20: US | AD20: 429
A21: 11141220 | B21: 45678 | C21: 2025 | D21: 1 | E21: 2025Q1 | F21: No | G21: None | H21: FALSE | I21: FALSE | J21: FALSE | K21: FALSE | L21: Overweight; Gynaecomastia; Emotional disorder | M21: Overweight | N21: Unknown | O21: FALSE | P21: 3 | Q21: RISPERIDONE | R21: RISPERDAL | S21: 48 | T21: Product Used For Unknown Indication | U21: Janssen Pharmaceuticals, Inc. | V21: Atypical Antipsychotic [EPC] | W21: 2 | X21: 2-3 Drugs | Z21: Unknown | AA21: Male | AC21: US | AD21: 431
A22: 11176570 | B22: 45667 | C22: 2025 | D22: 1 | E22: 2025Q1 | F22: Yes | G22: Hospitalization; Life-Threatening | H22: FALSE | I22: TRUE | J22: TRUE | K22: FALSE | L22: Intentional overdose; Hypoglycaemia; Metabolic acidosis; Acute kidney injury; Oliguria | M22: Intentional overdose | N22: Recovered | O22: TRUE | P22: 13 | Q22: AMLODIPINE | R22: SDAMLO; NORLIQVA; KATERZIA | S22: 48 | T22: Hypertension | U22: Pangea Pharmaceuticals, Llc; Cmp Pharma, Inc.; Azurity Pharmaceuticals, Inc. | V22: Dihydropyridine Calcium Channel Blocker [EPC]; Calcium Channel Blocker [EPC] | W22: 2 | X22: 2-3 Drugs | Z22: Unknown | AA22: Unknown | AC22: BE | AD22: 442
A23: 11198503 | B23: 45687 | C23: 2025 | D23: 1 | E23: 2025Q1 | F23: Yes | G23: Hospitalization; Life-Threatening; Disability; Congenital Anomaly | H23: FALSE | I23: TRUE | J23: TRUE | K23: TRUE | L23: Synovitis; Rheumatoid factor positive; Drug hypersensitivity; C-reactive protein increased; Red blood cell sedimentation rate increased | M23: Synovitis | N23: Unknown; Not Recovered | O23: FALSE | P23: 61 | Q23: ETANERCEPT | R23: ENBREL | S23: 58 | T23: Rheumatoid Arthritis | U23: Immunex Corporation | V23: Tumor Necrosis Factor Blocker [EPC] | W23: 88 | X23: Polypharmacy(6+) | Y23: 67 | Z23: Senior(66-80) | AA23: Female | AB23: 73 | AC23: CA | AD23: 422
A24: 11202456 | B24: 45686 | C24: 2025 | D24: 1 | E24: 2025Q1 | F24: Yes | G24: None | H24: FALSE | I24: FALSE | J24: FALSE | K24: FALSE | L24: Bronchitis; Urinary tract infection; Pneumonia; Body temperature decreased; Pain | M24: Bronchitis | N24: Unknown; Not Recovered; Recovered | O24: FALSE | P24: 12 | Q24: OMALIZUMAB | R24: XOLAIR | S24: 58 | T24: Asthma | U24: Genentech, Inc. | V24: Anti-IgE [EPC] | W24: 14 | X24: Polypharmacy(6+) | Y24: 56 | Z24: Middle-Aged(41-65) | AA24: Female | AC24: CA | AD24: 423
A25: 11242177 | B25: 45664 | C25: 2025 | D25: 1 | E25: 2025Q1 | F25: Yes | G25: None | H25: FALSE | I25: FALSE | J25: FALSE | K25: FALSE | L25: Leukopenia | M25: Leukopenia | N25: Recovering | O25: FALSE | P25: 1 | Q25: PEGINTRON | R25: Unknown | S25: 58 | T25: Cholangiocarcinoma | U25: Unknown | V25: Unknown | W25: 2 | X25: 2-3 Drugs | Z25: Unknown | AA25: Unknown | AC25: JP | AD25: 445
A26: 11242178 | B26: 45660 | C26: 2025 | D26: 1 | E26: 2025Q1 | F26: Yes | G26: None | H26: FALSE | I26: FALSE | J26: FALSE | K26: FALSE | L26: Thrombocytopenia | M26: Thrombocytopenia | N26: Unknown | O26: FALSE | P26: 1 | Q26: PEGINTRON | R26: Unknown | S26: 58 | T26: Cholangiocarcinoma | U26: Unknown | V26: Unknown | W26: 4 | X26: 4-5 Drugs | Z26: Unknown | AA26: Unknown | AC26: JP | AD26: 449
A27: 11322501 | B27: 45681 | C27: 2025 | D27: 1 | E27: 2025Q1 | F27: Yes | G27: Hospitalization | H27: FALSE | I27: TRUE | J27: FALSE | K27: FALSE | L27: Diarrhoea; Electrolyte imbalance; Gastrointestinal infection; Hypoglycaemia; Hyponatraemic seizure | M27: Diarrhoea | N27: Recovered | O27: TRUE | P27: 11 | Q27: SOMATROPIN | R27: NORDITROPIN; HUMATROPE; SEROSTIM; NUTROPIN AQ NUSPIN 10; NUTROPIN AQ NUSPIN 5 | S27: 58 | T27: Growth Hormone Deficiency | U27: Novo Nordisk; Eli Lilly And Company; Emd Serono, Inc.; Genentech, Inc.; Pfizer Laboratories Div Pfizer Inc | V27: Recombinant Human Growth Hormone [EPC] | W27: 7 | X27: Polypharmacy(6+) | Y27: 2 | Z27: Infant(0-2) | AA27: Female | AC27: CA | AD27: 428
A28: 11342116 | B28: 45664 | C28: 2025 | D28: 1 | E28: 2025Q1 | F28: Yes | G28: Hospitalization | H28: FALSE | I28: TRUE | J28: FALSE | K28: FALSE | L28: Cardiac flutter; Hypertension; Atrial fibrillation; Tachycardia; Presyncope | M28: Cardiac flutter | N28: Unknown; Not Recovered | O28: FALSE | P28: 16 | Q28: PEGVISOMANT | R28: SOMAVERT | S28: 58 | T28: Acromegaly | U28: Pharmacia & Upjohn Company Llc | V28: Unknown | W28: 13 | X28: Polypharmacy(6+) | Y28: 82 | Z28: Elderly(81+) | AA28: Female | AB28: 87 | AC28: US | AD28: 445
A29: 11404045 | B29: 45670 | C29: 2025 | D29: 1 | E29: 2025Q1 | F29: Yes | G29: Hospitalization; Life-Threatening | H29: FALSE | I29: TRUE | J29: TRUE | K29: FALSE | L29: Septic shock; Bacterial sepsis; Febrile bone marrow aplasia; Acute kidney injury; Deep vein thrombosis | M29: Septic shock | N29: Recovered | O29: TRUE | P29: 8 | Q29: FONDAPARINUX | R29: Unknown | S29: 58 | T29: Product Used For Unknown Indication | U29: Unknown | V29: Unknown | W29: 36 | X29: Polypharmacy(6+) | Y29: 60 | Z29: Middle-Aged(41-65) | AA29: Male | AB29: 80 | AC29: FR | AD29: 439
A30: 11489618 | B30: 45663 | C30: 2025 | D30: 1 | E30: 2025Q1 | F30: Yes | G30: None | H30: FALSE | I30: FALSE | J30: FALSE | K30: FALSE | L30: Heavy menstrual bleeding | M30: Heavy menstrual bleeding | N30: Recovered | O30: TRUE | P30: 1 | Q30: SODIUM OXYBATE | R30: XYREM | S30: 48 | T30: Narcolepsy | U30: Jazz Pharmaceuticals, Inc. | V30: Unknown | W30: 11 | X30: Polypharmacy(6+) | Y30: 39 | Z30: Adult(19-40) | AA30: Female | AB30: 61.7 | AC30: US | AD30: 446
A31: 11591887 | B31: 45681 | C31: 2025 | D31: 1 | E31: 2025Q1 | F31: Yes | G31: Hospitalization | H31: FALSE | I31: TRUE | J31: FALSE | K31: FALSE | L31: Influenza; Hypersensitivity; Urticaria; Pruritus; Lower respiratory tract infection | M31: Influenza | N31: Unknown; Not Recovered; Recovering | O31: FALSE | P31: 34 | Q31: OMALIZUMAB | R31: XOLAIR | S31: 58 | T31: Asthma | U31: Genentech, Inc. | V31: Anti-IgE [EPC] | W31: 34 | X31: Polypharmacy(6+) | Y31: 55 | Z31: Middle-Aged(41-65) | AA31: Female | AC31: CA | AD31: 428
A32: 11610486 | B32: 45672 | C32: 2025 | D32: 1 | E32: 2025Q1 | F32: Yes | G32: Hospitalization | H32: FALSE | I32: TRUE | J32: FALSE | K32: FALSE | L32: Terminal ileitis; Neutropenia; Hypokalaemia | M32: Terminal ileitis | N32: Recovered | O32: TRUE | P32: 3 | Q32: CAPECITABINE | R32: CAPECITABINE; CAPECITABINE 150MG; XELODA; CAPECITABINE 500MG | S32: 65 | T32: Adenocarcinoma | U32: Cipla Usa Inc.; Bluepoint Laboratories; Dr. Reddy'S Laboratories Limited; Northstar Rxllc; Teva Pharmaceuticals Usa, Inc. | V32: Nucleoside Metabolic Inhibitor [EPC] | W32: 5 | X32: 4-5 Drugs | Y32: 61 | Z32: Middle-Aged(41-65) | AA32: Female | AC32: HK | AD32: 437
A33: 11624304 | B33: 45683 | C33: 2025 | D33: 1 | E33: 2025Q1 | F33: No | G33: None | H33: FALSE | I33: FALSE | J33: FALSE | K33: FALSE | L33: Rash; Inappropriate schedule of product administration; Product dose omission issue; Product use issue | M33: Rash | N33: Unknown; Not Recovered | O33: FALSE | P33: 4 | Q33: SITAGLIPTIN AND METFORMIN HYDROCHLORIDE | R33: JANUMET; JANUMET XR | S33: 48 | T33: Diabetes Mellitus | U33: Merck Sharp & Dohme Llc | V33: Unknown | W33: 1 | X33: Single | Y33: 56 | Z33: Middle-Aged(41-65) | AA33: Female | AC33: US | AD33: 426
A34: 11633442 | B34: 45677 | C34: 2025 | D34: 1 | E34: 2025Q1 | F34: Yes | G34: None | H34: FALSE | I34: FALSE | J34: FALSE | K34: FALSE | L34: Infection; Pain; Migraine; Urticaria | M34: Infection | N34: Unknown | O34: FALSE | P34: 4 | Q34: HUMAN IMMUNOGLOBULIN G | R34: ASCENIV; QIVIGY KTHM | S34: Unknown | T34: Combined Immunodeficiency | U34: Adma Biologics, Inc.; Kedrion S.P.A. | V34: Human Immunoglobulin G [EPC] | W34: 2 | X34: 2-3 Drugs | Z34: Unknown | AA34: Female | AC34: US | AD34: 432
A35: 11706030 | B35: 45685 | C35: 2025 | D35: 1 | E35: 2025Q1 | F35: Yes | G35: Hospitalization | H35: FALSE | I35: TRUE | J35: FALSE | K35: FALSE | L35: Myocardial infarction; Supraventricular tachycardia; Feeling drunk; Brain fog | M35: Myocardial infarction | N35: Unknown | O35: FALSE | P35: 4 | Q35: CONJUGATED ESTROGENS; ESTROGENS, CONJUGATED | R35: PREMARIN VAGINAL; PREMARIN | S35: Unknown | T35: Oestrogen Replacement Therapy | U35: Wyeth Pharmaceuticals Llc, A Subsidiary Of Pfizer Inc. | V35: Estrogen [EPC] | W35: 2 | X35: 2-3 Drugs | Y35: 53 | Z35: Middle-Aged(41-65) | AA35: Female | AB35: 69 | AC35: US | AD35: 424
A36: 11713362 | B36: 45685 | C36: 2025 | D36: 1 | E36: 2025Q1 | F36: Yes | G36: None | H36: FALSE | I36: FALSE | J36: FALSE | K36: FALSE | L36: Blindness; Visual acuity reduced | M36: Blindness | N36: Unknown; Not Recovered | O36: FALSE | P36: 2 | Q36: ETANERCEPT | R36: ENBREL | S36: 65 | T36: Rheumatoid Arthritis | U36: Immunex Corporation | V36: Tumor Necrosis Factor Blocker [EPC] | W36: 1 | X36: Single | Y36: 58 | Z36: Middle-Aged(41-65) | AA36: Female | AC36: US | AD36: 424
A37: 11749584 | B37: 45677 | C37: 2025 | D37: 1 | E37: 2025Q1 | F37: Yes | G37: None | H37: FALSE | I37: FALSE | J37: FALSE | K37: FALSE | L37: Tooth abscess; Pneumonia; Body temperature decreased; Stress; Blood pressure decreased | M37: Tooth abscess | N37: Unknown; Recovered; Recovering | O37: TRUE | P37: 27 | Q37: OMALIZUMAB | R37: XOLAIR | S37: 58 | T37: Asthma | U37: Genentech, Inc. | V37: Anti-IgE [EPC] | W37: 34 | X37: Polypharmacy(6+) | Y37: 56 | Z37: Middle-Aged(41-65) | AA37: Female | AB37: 75 | AC37: CA | AD37: 432
A38: 11817639 | B38: 45673 | C38: 2025 | D38: 1 | E38: 2025Q1 | F38: No | G38: None | H38: FALSE | I38: FALSE | J38: FALSE | K38: FALSE | L38: Obesity; Gynaecomastia; Emotional disorder; Off label use | M38: Obesity | N38: Unknown | O38: FALSE | P38: 4 | Q38: RISPERIDONE | R38: RISPERDAL | S38: 48 | T38: Anxiety | U38: Janssen Pharmaceuticals, Inc. | V38: Atypical Antipsychotic [EPC] | W38: 2 | X38: 2-3 Drugs | Y38: 5 | Z38: Child(3-12) | AA38: Male | AB38: 43.09 | AC38: US | AD38: 436
A39: 11844191 | B39: 45686 | C39: 2025 | D39: 1 | E39: 2025Q1 | F39: Yes | G39: None | H39: FALSE | I39: FALSE | J39: FALSE | K39: FALSE | L39: Joint space narrowing | M39: Joint space narrowing | N39: Recovered | O39: TRUE | P39: 1 | Q39: DIMETHYL FUMARATE | R39: TECFIDERA | S39: 50 | T39: Multiple Sclerosis | U39: Biogen Inc. | V39: Unknown | W39: 6 | X39: Polypharmacy(6+) | Z39: Unknown | AA39: Female | AC39: US | AD39: 423
A40: 11844688 | B40: 45677 | C40: 2025 | D40: 1 | E40: 2025Q1 | F40: Yes | G40: None | H40: FALSE | I40: FALSE | J40: FALSE | K40: FALSE | L40: Weight increased; Joint swelling; Drug ineffective; Bone swelling; Arthralgia | M40: Weight increased | N40: Unknown; Not Recovered; Recovering | O40: FALSE | P40: 46 | Q40: TOCILIZUMAB | R40: ACTEMRA | S40: 42 | T40: Rheumatoid Arthritis | U40: Genentech, Inc. | V40: Interleukin-6 Receptor Antagonist [EPC] | W40: 31 | X40: Polypharmacy(6+) | Y40: 42 | Z40: Middle-Aged(41-65) | AA40: Female | AB40: 105 | AC40: CA | AD40: 432
...

Sheet MedDRA Mapping
A1: report_id | B1: primary_reaction | C1: meddra_pt | D1: meddra_soc | E1: causality | F1: signal_type | G1: serious
A2: 10136674 | B2: Pneumonia | C2: Pneumonia | D2: Infections and infestations | E2: =IFERROR(VLOOKUP(B2,Signal_detection!$A$1:$C$22,2,FALSE),"") -> Probable | F2: =IFERROR(VLOOKUP(B2,Signal_detection!$A$1:$C$22,3,FALSE),"") -> Infection signal | G2: Yes
A3: 10233235 | B3: Cerebrovascular accident | C3: Cerebrovascular accident | D3: Nervous system disorders | E3: =IFERROR(VLOOKUP(B3,Signal_detection!$A$1:$C$22,2,FALSE),"") -> Probable | F3: =IFERROR(VLOOKUP(B3,Signal_detection!$A$1:$C$22,3,FALSE),"") -> Neurological signal | G3: Yes
A4: 10285496 | B4: Alopecia | C4: Alopecia | D4: Skin and subcutaneous tissue disorders | E4: =IFERROR(VLOOKUP(B4,Signal_detection!$A$1:$C$22,2,FALSE),"") -> Possible | F4: =IFERROR(VLOOKUP(B4,Signal_detection!$A$1:$C$22,3,FALSE),"") -> Non-serious ADR | G4: Yes
A5: 10356309 | B5: Pneumonia | C5: Pneumonia | D5: Infections and infestations | E5: =IFERROR(VLOOKUP(B5,Signal_detection!$A$1:$C$22,2,FALSE),"") -> Probable | F5: =IFERROR(VLOOKUP(B5,Signal_detection!$A$1:$C$22,3,FALSE),"") -> Infection signal | G5: Yes
A6: 10450109 | B6: Retinal phototoxicity | E6: =IFERROR(VLOOKUP(B6,Signal_detection!$A$1:$C$22,2,FALSE),"") | F6: =IFERROR(VLOOKUP(B6,Signal_detection!$A$1:$C$22,3,FALSE),"") | G6: Yes
A7: 10607501 | B7: Death | C7: Death | D7: General disorders and administration site conditions | E7: =IFERROR(VLOOKUP(B7,Signal_detection!$A$1:$C$22,2,FALSE),"") | F7: =IFERROR(VLOOKUP(B7,Signal_detection!$A$1:$C$22,3,FALSE),"") | G7: Yes
A8: 10660602 | B8: Overdose | E8: =IFERROR(VLOOKUP(B8,Signal_detection!$A$1:$C$22,2,FALSE),"") | F8: =IFERROR(VLOOKUP(B8,Signal_detection!$A$1:$C$22,3,FALSE),"") | G8: Yes
A9: 10675738 | B9: Pyoderma gangrenosum | E9: =IFERROR(VLOOKUP(B9,Signal_detection!$A$1:$C$22,2,FALSE),"") | F9: =IFERROR(VLOOKUP(B9,Signal_detection!$A$1:$C$22,3,FALSE),"") | G9: Yes
A10: 10786604 | B10: Drug resistance | E10: =IFERROR(VLOOKUP(B10,Signal_detection!$A$1:$C$22,2,FALSE),"") | F10: =IFERROR(VLOOKUP(B10,Signal_detection!$A$1:$C$22,3,FALSE),"") | G10: No
A11: 10853820 | B11: Withdrawal syndrome | E11: =IFERROR(VLOOKUP(B11,Signal_detection!$A$1:$C$22,2,FALSE),"") | F11: =IFERROR(VLOOKUP(B11,Signal_detection!$A$1:$C$22,3,FALSE),"") | G11: Yes
A12: 10876704 | B12: Serotonin syndrome | E12: =IFERROR(VLOOKUP(B12,Signal_detection!$A$1:$C$22,2,FALSE),"") | F12: =IFERROR(VLOOKUP(B12,Signal_detection!$A$1:$C$22,3,FALSE),"") | G12: Yes
A13: 10928940 | B13: Gynaecomastia | C13: Gynaecomastia | D13: Endocrine disorders | E13: =IFERROR(VLOOKUP(B13,Signal_detection!$A$1:$C$22,2,FALSE),"") | F13: =IFERROR(VLOOKUP(B13,Signal_detection!$A$1:$C$22,3,FALSE),"") | G13: Yes
A14: 10943373 | B14: Emotional disorder | E14: =IFERROR(VLOOKUP(B14,Signal_detection!$A$1:$C$22,2,FALSE),"") | F14: =IFERROR(VLOOKUP(B14,Signal_detection!$A$1:$C$22,3,FALSE),"") | G14: No
A15: 10943649 | B15: Gynaecomastia | C15: Gynaecomastia | D15: Endocrine disorders | E15: =IFERROR(VLOOKUP(B15,Signal_detection!$A$1:$C$22,2,FALSE),"") | F15: =IFERROR(VLOOKUP(B15,Signal_detection!$A$1:$C$22,3,FALSE),"") | G15: No
A16: 10946040 | B16: Gynaecomastia | C16: Gynaecomastia | D16: Endocrine disorders | E16: =IFERROR(VLOOKUP(B16,Signal_detection!$A$1:$C$22,2,FALSE),"") | F16: =IFERROR(VLOOKUP(B16,Signal_detection!$A$1:$C$22,3,FALSE),"") | G16: No
A17: 10975876 | B17: Rectal haemorrhage | E17: =IFERROR(VLOOKUP(B17,Signal_detection!$A$1:$C$22,2,FALSE),"") | F17: =IFERROR(VLOOKUP(B17,Signal_detection!$A$1:$C$22,3,FALSE),"") | G17: Yes
A18: 11069598 | B18: Abscess oral | E18: =IFERROR(VLOOKUP(B18,Signal_detection!$A$1:$C$22,2,FALSE),"") | F18: =IFERROR(VLOOKUP(B18,Signal_detection!$A$1:$C$22,3,FALSE),"") | G18: Yes
A19: 11101084 | B19: Peritonitis | E19: =IFERROR(VLOOKUP(B19,Signal_detection!$A$1:$C$22,2,FALSE),"") | F19: =IFERROR(VLOOKUP(B19,Signal_detection!$A$1:$C$22,3,FALSE),"") | G19: Yes
A20: 11140907 | B20: Gynaecomastia | C20: Gynaecomastia | D20: Endocrine disorders | E20: =IFERROR(VLOOKUP(B20,Signal_detection!$A$1:$C$22,2,FALSE),"") | F20: =IFERROR(VLOOKUP(B20,Signal_detection!$A$1:$C$22,3,FALSE),"") | G20: No
A21: 11141220 | B21: Overweight | E21: =IFERROR(VLOOKUP(B21,Signal_detection!$A$1:$C$22,2,FALSE),"") | F21: =IFERROR(VLOOKUP(B21,Signal_detection!$A$1:$C$22,3,FALSE),"") | G21: No
A22: 11176570 | B22: Intentional overdose | E22: =IFERROR(VLOOKUP(B22,Signal_detection!$A$1:$C$22,2,FALSE),"") | F22: =IFERROR(VLOOKUP(B22,Signal_detection!$A$1:$C$22,3,FALSE),"") | G22: Yes
A23: 11198503 | B23: Synovitis | E23: =IFERROR(VLOOKUP(B23,Signal_detection!$A$1:$C$22,2,FALSE),"") | F23: =IFERROR(VLOOKUP(B23,Signal_detection!$A$1:$C$22,3,FALSE),"") | G23: Yes
A24: 11202456 | B24: Bronchitis | E24: =IFERROR(VLOOKUP(B24,Signal_detection!$A$1:$C$22,2,FALSE),"") | F24: =IFERROR(VLOOKUP(B24,Signal_detection!$A$1:$C$22,3,FALSE),"") | G24: Yes
A25: 11242177 | B25: Leukopenia | C25: Leukopenia | D25: Blood and lymphatic system disorders | E25: =IFERROR(VLOOKUP(B25,Signal_detection!$A$1:$C$22,2,FALSE),"") -> Probable | F25: =IFERROR(VLOOKUP(B25,Signal_detection!$A$1:$C$22,3,FALSE),"") -> Hematologic signal | G25: Yes
A26: 11242178 | B26: Thrombocytopenia | E26: =IFERROR(VLOOKUP(B26,Signal_detection!$A$1:$C$22,2,FALSE),"") | F26: =IFERROR(VLOOKUP(B26,Signal_detection!$A$1:$C$22,3,FALSE),"") | G26: Yes
A27: 11322501 | B27: Diarrhoea | C27: Diarrhoea | D27: Gastrointestinal disorders | E27: =IFERROR(VLOOKUP(B27,Signal_detection!$A$1:$C$22,2,FALSE),"") -> Possible | F27: =IFERROR(VLOOKUP(B27,Signal_detection!$A$1:$C$22,3,FALSE),"") -> GI ADR | G27: Yes
A28: 11342116 | B28: Cardiac flutter | E28: =IFERROR(VLOOKUP(B28,Signal_detection!$A$1:$C$22,2,FALSE),"") | F28: =IFERROR(VLOOKUP(B28,Signal_detection!$A$1:$C$22,3,FALSE),"") | G28: Yes
A29: 11404045 | B29: Septic shock | E29: =IFERROR(VLOOKUP(B29,Signal_detection!$A$1:$C$22,2,FALSE),"") | F29: =IFERROR(VLOOKUP(B29,Signal_detection!$A$1:$C$22,3,FALSE),"") | G29: Yes
A30: 11489618 | B30: Heavy menstrual bleeding | E30: =IFERROR(VLOOKUP(B30,Signal_detection!$A$1:$C$22,2,FALSE),"") | F30: =IFERROR(VLOOKUP(B30,Signal_detection!$A$1:$C$22,3,FALSE),"") | G30: Yes
A31: 11591887 | B31: Influenza | E31: =IFERROR(VLOOKUP(B31,Signal_detection!$A$1:$C$22,2,FALSE),"") | F31: =IFERROR(VLOOKUP(B31,Signal_detection!$A$1:$C$22,3,FALSE),"") | G31: Yes
A32: 11610486 | B32: Terminal ileitis | E32: =IFERROR(VLOOKUP(B32,Signal_detection!$A$1:$C$22,2,FALSE),"") | F32: =IFERROR(VLOOKUP(B32,Signal_detection!$A$1:$C$22,3,FALSE),"") | G32: Yes
A33: 11624304 | B33: Rash | C33: Rash | D33: Skin and subcutaneous tissue disorders | E33: =IFERROR(VLOOKUP(B33,Signal_detection!$A$1:$C$22,2,FALSE),"") -> Possible | F33: =IFERROR(VLOOKUP(B33,Signal_detection!$A$1:$C$22,3,FALSE),"") -> Skin ADR | G33: No
A34: 11633442 | B34: Infection | E34: =IFERROR(VLOOKUP(B34,Signal_detection!$A$1:$C$22,2,FALSE),"") | F34: =IFERROR(VLOOKUP(B34,Signal_detection!$A$1:$C$22,3,FALSE),"") | G34: Yes
A35: 11706030 | B35: Myocardial infarction | E35: =IFERROR(VLOOKUP(B35,Signal_detection!$A$1:$C$22,2,FALSE),"") | F35: =IFERROR(VLOOKUP(B35,Signal_detection!$A$1:$C$22,3,FALSE),"") | G35: Yes
A36: 11713362 | B36: Blindness | E36: =IFERROR(VLOOKUP(B36,Signal_detection!$A$1:$C$22,2,FALSE),"") | F36: =IFERROR(VLOOKUP(B36,Signal_detection!$A$1:$C$22,3,FALSE),"") | G36: Yes
A37: 11749584 | B37: Tooth abscess | E37: =IFERROR(VLOOKUP(B37,Signal_detection!$A$1:$C$22,2,FALSE),"") | F37: =IFERROR(VLOOKUP(B37,Signal_detection!$A$1:$C$22,3,FALSE),"") | G37: Yes
A38: 11817639 | B38: Obesity | E38: =IFERROR(VLOOKUP(B38,Signal_detection!$A$1:$C$22,2,FALSE),"") | F38: =IFERROR(VLOOKUP(B38,Signal_detection!$A$1:$C$22,3,FALSE),"") | G38: No
A39: 11844191 | B39: Joint space narrowing | E39: =IFERROR(VLOOKUP(B39,Signal_detection!$A$1:$C$22,2,FALSE),"") | F39: =IFERROR(VLOOKUP(B39,Signal_detection!$A$1:$C$22,3,FALSE),"") | G39: Yes
A40: 11844688 | B40: Weight increased | C40: Weight increased | D40: Metabolism and nutrition disorders | E40: =IFERROR(VLOOKUP(B40,Signal_detection!$A$1:$C$22,2,FALSE),"") | F40: =IFERROR(VLOOKUP(B40,Signal_detection!$A$1:$C$22,3,FALSE),"") | G40: Yes
...

Sheet TOP Reported ADR's 
A1: primary_reaction | B1: meddra_pt | C1: meddra_soc
A2: Foetal exposure during delivery | B2: Foetal exposure during delivery | C2: Pregnancy, puerperium and perinatal conditions
A3: Immune-mediated adverse reaction | B3: Immune-mediated adverse reaction | C3: Immune system disorders
A4: Pneumonia | B4: Pneumonia | C4: Infections and infestations
A5: Drug hypersensitivity | B5: Drug hypersensitivity | C5: Immune system disorders
A6: Death | B6: Death | C6: General disorders and administration site conditions
A7: Drug ineffective | B7: Drug ineffective | C7: General disorders and administration site conditions
A8: Maternal exposure during pregnancy | B8: Maternal exposure during pregnancy | C8: Pregnancy, puerperium and perinatal conditions
A9: Gynaecomastia | B9: Gynaecomastia | C9: Endocrine disorders
A10: Anaphylactic reaction | B10: Anaphylactic reaction | C10: Immune system disorders
A11: Alopecia | B11: Alopecia | C11: Skin and subcutaneous tissue disorders
A12: Fatigue | B12: Fatigue | C12: General disorders and administration site conditions
... A33: Leukopenia | B33: Leukopenia | C33: Blood and lymphatic system disorders

Sheet Signal_detection
A1: Primary Reaction | B1: Suggested Causality | C1: Signal Type
A2: Pneumonia | B2: Probable | C2: Infection signal
A3: Immune-mediated adverse reaction | B3: Probable | C3: Immune signal
A4: Drug hypersensitivity | B4: Probable | C4: Hypersensitivity signal
A5: Anaphylactic reaction | B5: Probable | C5: Serious allergy signal
A6: Sepsis | B6: Probable | C6: Infection signal
A7: Fatigue | B7: Possible | C7: General ADR
A8: Rash | B8: Possible | C8: Skin ADR
A9: Diarrhoea | B9: Possible | C9: GI ADR
A10: Alopecia | B10: Possible | C10: Non-serious ADR
A11: Acute kidney injury | B11: Probable | C11: Renal safety signal
A12: Renal injury | B12: Probable | C12: Renal safety signal
... A22: No adverse event | B22: Unlikely | C22: Non-case

Sheet Narratives
A1: case_id | B1: narrative
A2: 10136674 | B2: A 23-year-old female patient with a medical history of psoriasis received Ustekinumab (STELARA) therapy. During the course of treatment, the patient developed pneumonia accompanied by staphylococcal infection and sepsis. The adverse events were considered serious due to hospitalization requirement. Appropriate medical management was initiated, and the patient subsequently recovered. Considering the temporal association between drug administration and onset of the adverse events, along with the known immunosuppressive profile of Ustekinumab, the causality assessment was determined to be probable. Continuous monitoring for serious infection-related adverse events is recommended during biologic therapy.
A3: 10233235 | B3: A patient receiving Temodal therapy for glioblastoma experienced a cerebrovascular accident during treatment. The adverse event was considered serious due to life-threatening clinical presentation. The outcome of the event was reported as unknown. Based on the temporal relationship between suspect drug exposure and onset of the neurological event, along with the seriousness of the reaction, causality was assessed as probable. Continuous monitoring for severe neurological adverse events is recommended during antineoplastic therapy.
A4: 15924100 | B4: A female patient receiving Letrozole (FEMARA) therapy for metastatic breast cancer developed neutropenia during the course of treatment. Additional adverse events including dyspepsia and nasopharyngitis were also reported. The adverse reaction was classified as serious based on medical significance. The outcome for neutropenia was reported as not recovered, while other associated events showed recovery. The patient was receiving concomitant medications as part of polypharmacy treatment. Based on the temporal relationship between Letrozole administration and onset of the hematologic adverse event, along with the known safety profile of aromatase inhibitor therapy, causality was assessed as probable. Continuous hematologic monitoring is recommended during treatment with endocrine therapy agents in oncology patients.
A5: 17390121 | B5: A patient receiving Acyclovir therapy for infection prophylaxis developed Fanconi syndrome during treatment. An additional event of off-label use was also reported. The adverse event outcome for Fanconi syndrome was reported as unknown, while the off-label use event was noted as recovering. The patient was receiving multiple concomitant medications as part of polypharmacy treatment. Fanconi syndrome was considered medically significant due to its potential renal and metabolic complications. Based on the temporal association between Acyclovir administration and onset of the renal tubular disorder, along with the known nephrotoxic potential associated with antiviral therapy, causality was assessed as probable. Continuous renal function monitoring is recommended during prolonged antiviral treatment, especially in patients receiving multiple concomitant therapies.
A6: 17793257 | B6: A 79-year-old female patient receiving Prednisone therapy following liver transplant developed COVID-19 infection and COVID-19 pneumonia during treatment. Additional events of off-label use and product use in unapproved indication were also reported. The adverse event was considered serious due to hospitalization. The clinical outcome was reported as unknown, with partial recovery noted for associated events. The patient was receiving multiple concomitant medications as part of polypharmacy therapy. Considering the patient’s immunosuppressed status, advanced age, corticosteroid exposure, and temporal relationship between therapy and onset of infection-related adverse events, causality was assessed as possible. Continuous monitoring for severe respiratory infections is recommended in elderly transplant patients receiving corticosteroid-based immunosuppressive therapy.

Sheet Dashboards
